Workbook

Sheet README
A1: Inventory Health & Lead-Time KPI Case (learning project)
A2: SYNTHETIC DATA - personal learning project. Not company data. No real savings or impact.
A4: Purpose | B4: Show how to turn inventory and process-timestamp data into manager-ready KPIs with live Excel formulas: safety stock, reorder point, days of cover, status classes, a top-10 exception list, and step-level lead-time analysis.
A5: Data | B5: ALL numbers are SYNTHETIC, generated with a fixed random seed (42) by build_case.py. 40 SKUs, 200 assembly orders. Nothing here comes from tesa, Airbus or any other company. Currency 'EUR' is a label only.
A6: How to read | B6: 1) Inputs: blue cells are editable assumptions/data. 2) Inventory_Health: per-SKU formulas + summary KPIs + chart. 3) Exceptions: top-10 SKUs by EUR exposure with a recommended action. 4) LeadTime_Analysis: event log, step durations, average / P90, bottleneck, data-quality checks, chart. 5) Recommendation: what a manager would do.
A7: Safety stock | B7: SS = z * SQRT( (L + R) * sigma_d^2 + mu_d^2 * sigma_L^2 ), all in weeks. L = lead time, R = review period, sigma_d = weekly demand std, mu_d = weekly demand mean, sigma_L = lead-time std. z = NORM.S.INV(target service level).
A8: Reorder point | B8: ROP = mu_d * (L + R) + SS (demand over the protection interval plus safety stock), compared against inventory position = on-hand + on-order.
A9: Status rules | B9: Stockout risk: inventory position < ROP. Overstock: not at risk AND days of cover (on-hand / daily demand) > overstock threshold (Inputs!B6). Otherwise Healthy. Rule order matters: stockout risk is tested first.
A10: Service-level proxy | B10: P(no stockout in protection interval) = NORM.S.DIST((IP - mu_d*(L+R)) / sigma_protection, TRUE). A cycle-service-level proxy, not a fill rate.
A11: Exposure / ranking | B11: Exposure (EUR) = shortfall to ROP x unit cost for stockout-risk SKUs; on-hand above the overstock threshold x unit cost for overstock SKUs; 0 if healthy. Ties are broken by row order. Top-10 uses RANK + INDEX/MATCH (works in Excel 2016+; no dynamic arrays).
A12: Lead time | B12: Each order has 6 timestamps (release + end of 5 steps). Step duration (h) = difference of consecutive timestamps. Rows with a missing timestamp or a negative duration are flagged and EXCLUDED from all averages/percentiles (whole row). P90 = PERCENTILE (inclusive).
A13: Limitations | B13: Demand is assumed normal and independent week to week; lead time normal and independent of demand; one echelon, no MOQ/lot sizes, no capacity limits, no stock-out cost model; ABC classes are assigned by design, not computed. Thresholds are illustrative. Step durations include waiting time. Results describe the synthetic data only and say nothing about any real operation.

Sheet Inputs
A1: Inputs (blue = editable)
A2: SYNTHETIC DATA - personal learning project. Not company data. No real savings or impact.
A3: Global parameters | E3: ABC class | F3: Target service level | H3: z-value = NORM.S.INV(service level) is computed per SKU on Inventory_Health.
A4: Review period (weeks) | B4: 1 | E4: A | F4: 0.98
A5: Days per week | B5: 7 | E5: B | F5: 0.95
A6: Overstock threshold (days of cover) | B6: 90 | E6: C | F6: 0.9
A7: High-variability CV threshold | B7: 0.6
A9: SKU master data and stock position (synthetic)
A11: SKU | B11: ABC class | C11: Weekly demand mean (units) | D11: Weekly demand std (units) | E11: Unit cost (EUR) | F11: On-hand stock (units) | G11: On-order (units) | H11: Supplier lead time (days) | I11: Lead-time std (days) | J11: Target service level | K11: Review period (weeks)
A12: SKU-001 | B12: A | C12: 509.6 | D12: 142.9 | E12: 32.36 | F12: 12672 | G12: 787 | H12: 32 | I12: 4.6 | J12: =VLOOKUP(B12,$E$4:$F$6,2,FALSE) -> 0.98 | K12: =$B$4 -> 1
A13: SKU-002 | B13: A | C13: 225.5 | D13: 66.4 | E13: 36.58 | F13: 212 | G13: 0 | H13: 23 | I13: 3.8 | J13: =VLOOKUP(B13,$E$4:$F$6,2,FALSE) -> 0.98 | K13: =$B$4 -> 1
A14: SKU-003 | B14: A | C14: 330.3 | D14: 54 | E14: 15.26 | F14: 2248 | G14: 386 | H14: 17 | I14: 3.8 | J14: =VLOOKUP(B14,$E$4:$F$6,2,FALSE) -> 0.98 | K14: =$B$4 -> 1
A15: SKU-004 | B15: A | C15: 255.9 | D15: 77 | E15: 32.98 | F15: 643 | G15: 0 | H15: 32 | I15: 2.7 | J15: =VLOOKUP(B15,$E$4:$F$6,2,FALSE) -> 0.98 | K15: =$B$4 -> 1
A16: SKU-005 | B16: A | C16: 453.9 | D16: 86.2 | E16: 14.87 | F16: 2489 | G16: 0 | H16: 14 | I16: 0.9 | J16: =VLOOKUP(B16,$E$4:$F$6,2,FALSE) -> 0.98 | K16: =$B$4 -> 1
A17: SKU-006 | B17: A | C17: 465.7 | D17: 73.8 | E17: 31.12 | F17: 802 | G17: 545 | H17: 19 | I17: 3.3 | J17: =VLOOKUP(B17,$E$4:$F$6,2,FALSE) -> 0.98 | K17: =$B$4 -> 1
A18: SKU-007 | B18: A | C18: 344.7 | D18: 117.6 | E18: 16.51 | F18: 2680 | G18: 196 | H18: 19 | I18: 3.1 | J18: =VLOOKUP(B18,$E$4:$F$6,2,FALSE) -> 0.98 | K18: =$B$4 -> 1
A19: SKU-008 | B19: A | C19: 431.7 | D19: 127.1 | E19: 28.07 | F19: 3649 | G19: 115 | H19: 29 | I19: 2.1 | J19: =VLOOKUP(B19,$E$4:$F$6,2,FALSE) -> 0.98 | K19: =$B$4 -> 1
A20: SKU-009 | B20: B | C20: 83.9 | D20: 24.1 | E20: 28.96 | F20: 843 | G20: 53 | H20: 26 | I20: 1.8 | J20: =VLOOKUP(B20,$E$4:$F$6,2,FALSE) -> 0.95 | K20: =$B$4 -> 1
A21: SKU-010 | B21: B | C21: 132.9 | D21: 54 | E21: 18.85 | F21: 1623 | G21: 391 | H21: 38 | I21: 8.3 | J21: =VLOOKUP(B21,$E$4:$F$6,2,FALSE) -> 0.95 | K21: =$B$4 -> 1
A22: SKU-011 | B22: B | C22: 65.2 | D22: 26.6 | E22: 28.82 | F22: 1611 | G22: 0 | H22: 32 | I22: 3.6 | J22: =VLOOKUP(B22,$E$4:$F$6,2,FALSE) -> 0.95 | K22: =$B$4 -> 1
A23: SKU-012 | B23: B | C23: 164.8 | D23: 54.3 | E23: 21.54 | F23: 1756 | G23: 342 | H23: 28 | I23: 2.1 | J23: =VLOOKUP(B23,$E$4:$F$6,2,FALSE) -> 0.95 | K23: =$B$4 -> 1
... A51: SKU-040 | B51: C | C51: 27.6 | D51: 16.7 | E51: 12.52 | F51: 255 | G51: 0 | H51: 46 | I51: 2.7 | J51: =VLOOKUP(B51,$E$4:$F$6,2,FALSE) -> 0.9 | K51: =$B$4 -> 1

Sheet Inventory_Health
A1: Inventory health - per-SKU formulas and summary KPIs
A2: SYNTHETIC DATA - personal learning project. Not company data. No real savings or impact.
A4: Summary KPIs
A5: Status | B5: SKUs | C5: Share of SKUs | D5: Inventory value EUR | E5: Share of value
A6: Stockout risk | B6: =COUNTIF($S$17:$S$56,A6) -> 12 | C6: =B6/$B$9 -> 0.3 | D6: =SUMIF($S$17:$S$56,A6,$R$17:$R$56) -> 83091.49 | E6: =D6/$D$9 -> 0.071274962
A7: Healthy | B7: =COUNTIF($S$17:$S$56,A7) -> 16 | C7: =B7/$B$9 -> 0.4 | D7: =SUMIF($S$17:$S$56,A7,$R$17:$R$56) -> 361702.22 | E7: =D7/$D$9 -> 0.31026417
A8: Overstock | B8: =COUNTIF($S$17:$S$56,A8) -> 12 | C8: =B8/$B$9 -> 0.3 | D8: =SUMIF($S$17:$S$56,A8,$R$17:$R$56) -> 720994.21 | E8: =D8/$D$9 -> 0.61846087
A9: Total | B9: =SUM(B6:B8) -> 40 | C9: =SUM(C6:C8) -> 1 | D9: =SUM(D6:D8) -> 1165787.9 | E9: =SUM(E6:E8) -> 1
A10: Exposure: stockout shortfall to ROP (EUR) | D10: =SUMIF($S$17:$S$56,"Stockout risk",$U$17:$U$56) -> 123207.98
A11: Exposure: overstock excess above threshold (EUR) | D11: =SUMIF($S$17:$S$56,"Overstock",$U$17:$U$56) -> 357768.13
A12: Average service-level proxy (SKU mean) | D12: =AVERAGE($T$17:$T$56) -> 0.7660211
A13: Median days of cover | D13: =MEDIAN($Q$17:$Q$56) -> 60.205944
A14: SKUs with high demand variability (master-data review) | D14: =COUNTIF($X$17:$X$56,"High variability") -> 12
A16: SKU | B16: Class | C16: Demand mean /wk | D16: Demand std /wk | E16: Unit cost EUR | F16: Target SL | G16: z | H16: L (weeks) | I16: R (weeks) | J16: sigma_L (weeks) | K16: sigma protection (units) | L16: Safety stock (units) | M16: Reorder point (units) | N16: On-hand | O16: On-order | P16: Inventory position | Q16: Days of cover | R16: Inventory value EUR | S16: Status | T16: Service-level proxy | U16: Exposure EUR | V16: Priority score | W16: Rank | X16: Data flag
A17: =Inputs!A12 -> SKU-001 | B17: =Inputs!B12 -> A | C17: =Inputs!C12 -> 509.6 | D17: =Inputs!D12 -> 142.9 | E17: =Inputs!E12 -> 32.36 | F17: =Inputs!J12 -> 0.98 | G17: =_xlfn.NORM.S.INV(F17) -> 2.0537489 | H17: =Inputs!H12/Inputs!$B$5 -> 4.5714286 | I17: =Inputs!K12 -> 1 | J17: =Inputs!I12/Inputs!$B$5 -> 0.65714286 | K17: =SQRT((H17+I17)*D17^2+C17^2*J17^2) -> 475.30566 | L17: =G17*K17 -> 976.15848 | M17: =C17*(H17+I17)+L17 -> 3815.3585 | N17: =Inputs!F12 -> 12672 | O17: =Inputs!G12 -> 787 | P17: =N17+O17 -> 13459 | Q17: =N17/(C17/Inputs!$B$5) -> 174.06593 | R17: =N17*E17 -> 410065.92 | S17: =IF(P17<M17,"Stockout risk",IF(Q17>Inputs!$B$6,"Overstock","Healthy")) -> Overstock | T17: =_xlfn.NORM.S.DIST((P17-C17*(H17+I17))/K17,TRUE) -> 1 | U17: =IF(S17="Stockout risk",(M17-P17)*E17,IF(S17="Overstock",MAX(0,N17-Inputs!$B$6*C17/Inputs!$B$5)*E17,0)) -> 198043.2 | V17: =U17-ROW()*0.000000001 -> 198043.2 | W17: =RANK(V17,$V$17:$V$56) -> 1 | X17: =IF(D17/C17>Inputs!$B$7,"High variability","")
A18: =Inputs!A13 -> SKU-002 | B18: =Inputs!B13 -> A | C18: =Inputs!C13 -> 225.5 | D18: =Inputs!D13 -> 66.4 | E18: =Inputs!E13 -> 36.58 | F18: =Inputs!J13 -> 0.98 | G18: =_xlfn.NORM.S.INV(F18) -> 2.0537489 | H18: =Inputs!H13/Inputs!$B$5 -> 3.2857143 | I18: =Inputs!K13 -> 1 | J18: =Inputs!I13/Inputs!$B$5 -> 0.54285714 | K18: =SQRT((H18+I18)*D18^2+C18^2*J18^2) -> 184.06738 | L18: =G18*K18 -> 378.02818 | M18: =C18*(H18+I18)+L18 -> 1344.4568 | N18: =Inputs!F13 -> 212 | O18: =Inputs!G13 -> 0 | P18: =N18+O18 -> 212 | Q18: =N18/(C18/Inputs!$B$5) -> 6.5809313 | R18: =N18*E18 -> 7754.96 | S18: =IF(P18<M18,"Stockout risk",IF(Q18>Inputs!$B$6,"Overstock","Healthy")) -> Stockout risk | T18: =_xlfn.NORM.S.DIST((P18-C18*(H18+I18))/K18,TRUE) -> 2.0777951e-05 | U18: =IF(S18="Stockout risk",(M18-P18)*E18,IF(S18="Overstock",MAX(0,N18-Inputs!$B$6*C18/Inputs!$B$5)*E18,0)) -> 41425.268 | V18: =U18-ROW()*0.000000001 -> 41425.268 | W18: =RANK(V18,$V$17:$V$56) -> 4 | X18: =IF(D18/C18>Inputs!$B$7,"High variability","")
A19: =Inputs!A14 -> SKU-003 | B19: =Inputs!B14 -> A | C19: =Inputs!C14 -> 330.3 | D19: =Inputs!D14 -> 54 | E19: =Inputs!E14 -> 15.26 | F19: =Inputs!J14 -> 0.98 | G19: =_xlfn.NORM.S.INV(F19) -> 2.0537489 | H19: =Inputs!H14/Inputs!$B$5 -> 2.4285714 | I19: =Inputs!K14 -> 1 | J19: =Inputs!I14/Inputs!$B$5 -> 0.54285714 | K19: =SQRT((H19+I19)*D19^2+C19^2*J19^2) -> 205.3004 | L19: =G19*K19 -> 421.63547 | M19: =C19*(H19+I19)+L19 -> 1554.0926 | N19: =Inputs!F14 -> 2248 | O19: =Inputs!G14 -> 386 | P19: =N19+O19 -> 2634 | Q19: =N19/(C19/Inputs!$B$5) -> 47.641538 | R19: =N19*E19 -> 34304.48 | S19: =IF(P19<M19,"Stockout risk",IF(Q19>Inputs!$B$6,"Overstock","Healthy")) -> Healthy | T19: =_xlfn.NORM.S.DIST((P19-C19*(H19+I19))/K19,TRUE) -> 1 | U19: =IF(S19="Stockout risk",(M19-P19)*E19,IF(S19="Overstock",MAX(0,N19-Inputs!$B$6*C19/Inputs!$B$5)*E19,0)) -> 0 | V19: =U19-ROW()*0.000000001 -> -1.9e-08 | W19: =RANK(V19,$V$17:$V$56) -> 25 | X19: =IF(D19/C19>Inputs!$B$7,"High variability","")
A20: =Inputs!A15 -> SKU-004 | B20: =Inputs!B15 -> A | C20: =Inputs!C15 -> 255.9 | D20: =Inputs!D15 -> 77 | E20: =Inputs!E15 -> 32.98 | F20: =Inputs!J15 -> 0.98 | G20: =_xlfn.NORM.S.INV(F20) -> 2.0537489 | H20: =Inputs!H15/Inputs!$B$5 -> 4.5714286 | I20: =Inputs!K15 -> 1 | J20: =Inputs!I15/Inputs!$B$5 -> 0.38571429 | K20: =SQRT((H20+I20)*D20^2+C20^2*J20^2) -> 206.82247 | L20: =G20*K20 -> 424.76143 | M20: =C20*(H20+I20)+L20 -> 1850.49 | N20: =Inputs!F15 -> 643 | O20: =Inputs!G15 -> 0 | P20: =N20+O20 -> 643 | Q20: =N20/(C20/Inputs!$B$5) -> 17.588902 | R20: =N20*E20 -> 21206.14 | S20: =IF(P20<M20,"Stockout risk",IF(Q20>Inputs!$B$6,"Overstock","Healthy")) -> Stockout risk | T20: =_xlfn.NORM.S.DIST((P20-C20*(H20+I20))/K20,TRUE) -> 7.6995607e-05 | U20: =IF(S20="Stockout risk",(M20-P20)*E20,IF(S20="Overstock",MAX(0,N20-Inputs!$B$6*C20/Inputs!$B$5)*E20,0)) -> 39823.02 | V20: =U20-ROW()*0.000000001 -> 39823.02 | W20: =RANK(V20,$V$17:$V$56) -> 5 | X20: =IF(D20/C20>Inputs!$B$7,"High variability","")
A21: =Inputs!A16 -> SKU-005 | B21: =Inputs!B16 -> A | C21: =Inputs!C16 -> 453.9 | D21: =Inputs!D16 -> 86.2 | E21: =Inputs!E16 -> 14.87 | F21: =Inputs!J16 -> 0.98 | G21: =_xlfn.NORM.S.INV(F21) -> 2.0537489 | H21: =Inputs!H16/Inputs!$B$5 -> 2 | I21: =Inputs!K16 -> 1 | J21: =Inputs!I16/Inputs!$B$5 -> 0.12857143 | K21: =SQRT((H21+I21)*D21^2+C21^2*J21^2) -> 160.30297 | L21: =G21*K21 -> 329.22205 | M21: =C21*(H21+I21)+L21 -> 1690.9221 | N21: =Inputs!F16 -> 2489 | O21: =Inputs!G16 -> 0 | P21: =N21+O21 -> 2489 | Q21: =N21/(C21/Inputs!$B$5) -> 38.385107 | R21: =N21*E21 -> 37011.43 | S21: =IF(P21<M21,"Stockout risk",IF(Q21>Inputs!$B$6,"Overstock","Healthy")) -> Healthy | T21: =_xlfn.NORM.S.DIST((P21-C21*(H21+I21))/K21,TRUE) -> 1 | U21: =IF(S21="Stockout risk",(M21-P21)*E21,IF(S21="Overstock",MAX(0,N21-Inputs!$B$6*C21/Inputs!$B$5)*E21,0)) -> 0 | V21: =U21-ROW()*0.000000001 -> -2.1e-08 | W21: =RANK(V21,$V$17:$V$56) -> 26 | X21: =IF(D21/C21>Inputs!$B$7,"High variability","")
A22: =Inputs!A17 -> SKU-006 | B22: =Inputs!B17 -> A | C22: =Inputs!C17 -> 465.7 | D22: =Inputs!D17 -> 73.8 | E22: =Inputs!E17 -> 31.12 | F22: =Inputs!J17 -> 0.98 | G22: =_xlfn.NORM.S.INV(F22) -> 2.0537489 | H22: =Inputs!H17/Inputs!$B$5 -> 2.7142857 | I22: =Inputs!K17 -> 1 | J22: =Inputs!I17/Inputs!$B$5 -> 0.47142857 | K22: =SQRT((H22+I22)*D22^2+C22^2*J22^2) -> 261.59 | L22: =G22*K22 -> 537.24018 | M22: =C22*(H22+I22)+L22 -> 2266.983 | N22: =Inputs!F17 -> 802 | O22: =Inputs!G17 -> 545 | P22: =N22+O22 -> 1347 | Q22: =N22/(C22/Inputs!$B$5) -> 12.054971 | R22: =N22*E22 -> 24958.24 | S22: =IF(P22<M22,"Stockout risk",IF(Q22>Inputs!$B$6,"Overstock","Healthy")) -> Stockout risk | T22: =_xlfn.NORM.S.DIST((P22-C22*(H22+I22))/K22,TRUE) -> 0.071714503 | U22: =IF(S22="Stockout risk",(M22-P22)*E22,IF(S22="Overstock",MAX(0,N22-Inputs!$B$6*C22/Inputs!$B$5)*E22,0)) -> 28629.872 | V22: =U22-ROW()*0.000000001 -> 28629.872 | W22: =RANK(V22,$V$17:$V$56) -> 6 | X22: =IF(D22/C22>Inputs!$B$7,"High variability","")
A23: =Inputs!A18 -> SKU-007 | B23: =Inputs!B18 -> A | C23: =Inputs!C18 -> 344.7 | D23: =Inputs!D18 -> 117.6 | E23: =Inputs!E18 -> 16.51 | F23: =Inputs!J18 -> 0.98 | G23: =_xlfn.NORM.S.INV(F23) -> 2.0537489 | H23: =Inputs!H18/Inputs!$B$5 -> 2.7142857 | I23: =Inputs!K18 -> 1 | J23: =Inputs!I18/Inputs!$B$5 -> 0.44285714 | K23: =SQRT((H23+I23)*D23^2+C23^2*J23^2) -> 273.25917 | L23: =G23*K23 -> 561.20573 | M23: =C23*(H23+I23)+L23 -> 1841.52 | N23: =Inputs!F18 -> 2680 | O23: =Inputs!G18 -> 196 | P23: =N23+O23 -> 2876 | Q23: =N23/(C23/Inputs!$B$5) -> 54.424137 | R23: =N23*E23 -> 44246.8 | S23: =IF(P23<M23,"Stockout risk",IF(Q23>Inputs!$B$6,"Overstock","Healthy")) -> Healthy | T23: =_xlfn.NORM.S.DIST((P23-C23*(H23+I23))/K23,TRUE) -> 1 | U23: =IF(S23="Stockout risk",(M23-P23)*E23,IF(S23="Overstock",MAX(0,N23-Inputs!$B$6*C23/Inputs!$B$5)*E23,0)) -> 0 | V23: =U23-ROW()*0.000000001 -> -2.3e-08 | W23: =RANK(V23,$V$17:$V$56) -> 27 | X23: =IF(D23/C23>Inputs!$B$7,"High variability","")
A24: =Inputs!A19 -> SKU-008 | B24: =Inputs!B19 -> A | C24: =Inputs!C19 -> 431.7 | D24: =Inputs!D19 -> 127.1 | E24: =Inputs!E19 -> 28.07 | F24: =Inputs!J19 -> 0.98 | G24: =_xlfn.NORM.S.INV(F24) -> 2.0537489 | H24: =Inputs!H19/Inputs!$B$5 -> 4.1428571 | I24: =Inputs!K19 -> 1 | J24: =Inputs!I19/Inputs!$B$5 -> 0.3 | K24: =SQRT((H24+I24)*D24^2+C24^2*J24^2) -> 315.99472 | L24: =G24*K24 -> 648.97381 | M24: =C24*(H24+I24)+L24 -> 2869.1452 | N24: =Inputs!F19 -> 3649 | O24: =Inputs!G19 -> 115 | P24: =N24+O24 -> 3764 | Q24: =N24/(C24/Inputs!$B$5) -> 59.168404 | R24: =N24*E24 -> 102427.43 | S24: =IF(P24<M24,"Stockout risk",IF(Q24>Inputs!$B$6,"Overstock","Healthy")) -> Healthy | T24: =_xlfn.NORM.S.DIST((P24-C24*(H24+I24))/K24,TRUE) -> 0.99999948 | U24: =IF(S24="Stockout risk",(M24-P24)*E24,IF(S24="Overstock",MAX(0,N24-Inputs!$B$6*C24/Inputs!$B$5)*E24,0)) -> 0 | V24: =U24-ROW()*0.000000001 -> -2.4e-08 | W24: =RANK(V24,$V$17:$V$56) -> 28 | X24: =IF(D24/C24>Inputs!$B$7,"High variability","")
A25: =Inputs!A20 -> SKU-009 | B25: =Inputs!B20 -> B | C25: =Inputs!C20 -> 83.9 | D25: =Inputs!D20 -> 24.1 | E25: =Inputs!E20 -> 28.96 | F25: =Inputs!J20 -> 0.95 | G25: =_xlfn.NORM.S.INV(F25) -> 1.6448536 | H25: =Inputs!H20/Inputs!$B$5 -> 3.7142857 | I25: =Inputs!K20 -> 1 | J25: =Inputs!I20/Inputs!$B$5 -> 0.25714286 | K25: =SQRT((H25+I25)*D25^2+C25^2*J25^2) -> 56.599948 | L25: =G25*K25 -> 93.098629 | M25: =C25*(H25+I25)+L25 -> 488.6272 | N25: =Inputs!F20 -> 843 | O25: =Inputs!G20 -> 53 | P25: =N25+O25 -> 896 | Q25: =N25/(C25/Inputs!$B$5) -> 70.333731 | R25: =N25*E25 -> 24413.28 | S25: =IF(P25<M25,"Stockout risk",IF(Q25>Inputs!$B$6,"Overstock","Healthy")) -> Healthy | T25: =_xlfn.NORM.S.DIST((P25-C25*(H25+I25))/K25,TRUE) -> 1 | U25: =IF(S25="Stockout risk",(M25-P25)*E25,IF(S25="Overstock",MAX(0,N25-Inputs!$B$6*C25/Inputs!$B$5)*E25,0)) -> 0 | V25: =U25-ROW()*0.000000001 -> -2.5e-08 | W25: =RANK(V25,$V$17:$V$56) -> 29 | X25: =IF(D25/C25>Inputs!$B$7,"High variability","")
A26: =Inputs!A21 -> SKU-010 | B26: =Inputs!B21 -> B | C26: =Inputs!C21 -> 132.9 | D26: =Inputs!D21 -> 54 | E26: =Inputs!E21 -> 18.85 | F26: =Inputs!J21 -> 0.95 | G26: =_xlfn.NORM.S.INV(F26) -> 1.6448536 | H26: =Inputs!H21/Inputs!$B$5 -> 5.4285714 | I26: =Inputs!K21 -> 1 | J26: =Inputs!I21/Inputs!$B$5 -> 1.1857143 | K26: =SQRT((H26+I26)*D26^2+C26^2*J26^2) -> 208.75254 | L26: =G26*K26 -> 343.36736 | M26: =C26*(H26+I26)+L26 -> 1197.7245 | N26: =Inputs!F21 -> 1623 | O26: =Inputs!G21 -> 391 | P26: =N26+O26 -> 2014 | Q26: =N26/(C26/Inputs!$B$5) -> 85.485327 | R26: =N26*E26 -> 30593.55 | S26: =IF(P26<M26,"Stockout risk",IF(Q26>Inputs!$B$6,"Overstock","Healthy")) -> Healthy | T26: =_xlfn.NORM.S.DIST((P26-C26*(H26+I26))/K26,TRUE) -> 0.99999999 | U26: =IF(S26="Stockout risk",(M26-P26)*E26,IF(S26="Overstock",MAX(0,N26-Inputs!$B$6*C26/Inputs!$B$5)*E26,0)) -> 0 | V26: =U26-ROW()*0.000000001 -> -2.6e-08 | W26: =RANK(V26,$V$17:$V$56) -> 30 | X26: =IF(D26/C26>Inputs!$B$7,"High variability","")
A27: =Inputs!A22 -> SKU-011 | B27: =Inputs!B22 -> B | C27: =Inputs!C22 -> 65.2 | D27: =Inputs!D22 -> 26.6 | E27: =Inputs!E22 -> 28.82 | F27: =Inputs!J22 -> 0.95 | G27: =_xlfn.NORM.S.INV(F27) -> 1.6448536 | H27: =Inputs!H22/Inputs!$B$5 -> 4.5714286 | I27: =Inputs!K22 -> 1 | J27: =Inputs!I22/Inputs!$B$5 -> 0.51428571 | K27: =SQRT((H27+I27)*D27^2+C27^2*J27^2) -> 71.179187 | L27: =G27*K27 -> 117.07934 | M27: =C27*(H27+I27)+L27 -> 480.33649 | N27: =Inputs!F22 -> 1611 | O27: =Inputs!G22 -> 0 | P27: =N27+O27 -> 1611 | Q27: =N27/(C27/Inputs!$B$5) -> 172.96012 | R27: =N27*E27 -> 46429.02 | S27: =IF(P27<M27,"Stockout risk",IF(Q27>Inputs!$B$6,"Overstock","Healthy")) -> Overstock | T27: =_xlfn.NORM.S.DIST((P27-C27*(H27+I27))/K27,TRUE) -> 1 | U27: =IF(S27="Stockout risk",(M27-P27)*E27,IF(S27="Overstock",MAX(0,N27-Inputs!$B$6*C27/Inputs!$B$5)*E27,0)) -> 22269.626 | V27: =U27-ROW()*0.000000001 -> 22269.626 | W27: =RANK(V27,$V$17:$V$56) -> 7 | X27: =IF(D27/C27>Inputs!$B$7,"High variability","")
A28: =Inputs!A23 -> SKU-012 | B28: =Inputs!B23 -> B | C28: =Inputs!C23 -> 164.8 | D28: =Inputs!D23 -> 54.3 | E28: =Inputs!E23 -> 21.54 | F28: =Inputs!J23 -> 0.95 | G28: =_xlfn.NORM.S.INV(F28) -> 1.6448536 | H28: =Inputs!H23/Inputs!$B$5 -> 4 | I28: =Inputs!K23 -> 1 | J28: =Inputs!I23/Inputs!$B$5 -> 0.3 | K28: =SQRT((H28+I28)*D28^2+C28^2*J28^2) -> 131.0983 | L28: =G28*K28 -> 215.63751 | M28: =C28*(H28+I28)+L28 -> 1039.6375 | N28: =Inputs!F23 -> 1756 | O28: =Inputs!G23 -> 342 | P28: =N28+O28 -> 2098 | Q28: =N28/(C28/Inputs!$B$5) -> 74.587379 | R28: =N28*E28 -> 37824.24 | S28: =IF(P28<M28,"Stockout risk",IF(Q28>Inputs!$B$6,"Overstock","Healthy")) -> Healthy | T28: =_xlfn.NORM.S.DIST((P28-C28*(H28+I28))/K28,TRUE) -> 1 | U28: =IF(S28="Stockout risk",(M28-P28)*E28,IF(S28="Overstock",MAX(0,N28-Inputs!$B$6*C28/Inputs!$B$5)*E28,0)) -> 0 | V28: =U28-ROW()*0.000000001 -> -2.8e-08 | W28: =RANK(V28,$V$17:$V$56) -> 31 | X28: =IF(D28/C28>Inputs!$B$7,"High variability","")
... A56: =Inputs!A51 -> SKU-040 | B56: =Inputs!B51 -> C | C56: =Inputs!C51 -> 27.6 | D56: =Inputs!D51 -> 16.7 | E56: =Inputs!E51 -> 12.52 | F56: =Inputs!J51 -> 0.9 | G56: =_xlfn.NORM.S.INV(F56) -> 1.2815516 | H56: =Inputs!H51/Inputs!$B$5 -> 6.5714286 | I56: =Inputs!K51 -> 1 | J56: =Inputs!I51/Inputs!$B$5 -> 0.38571429 | K56: =SQRT((H56+I56)*D56^2+C56^2*J56^2) -> 47.169131 | L56: =G56*K56 -> 60.449674 | M56: =C56*(H56+I56)+L56 -> 269.4211 | N56: =Inputs!F51 -> 255 | O56: =Inputs!G51 -> 0 | P56: =N56+O56 -> 255 | Q56: =N56/(C56/Inputs!$B$5) -> 64.673913 | R56: =N56*E56 -> 3192.6 | S56: =IF(P56<M56,"Stockout risk",IF(Q56>Inputs!$B$6,"Overstock","Healthy")) -> Stockout risk | T56: =_xlfn.NORM.S.DIST((P56-C56*(H56+I56))/K56,TRUE) -> 0.83542311 | U56: =IF(S56="Stockout risk",(M56-P56)*E56,IF(S56="Overstock",MAX(0,N56-Inputs!$B$6*C56/Inputs!$B$5)*E56,0)) -> 180.5522 | V56: =U56-ROW()*0.000000001 -> 180.5522 | W56: =RANK(V56,$V$17:$V$56) -> 22 | X56: =IF(D56/C56>Inputs!$B$7,"High variability","") -> High variability

Sheet Exceptions
A1: Exceptions - top 10 SKUs needing action (by EUR exposure)
A2: SYNTHETIC DATA - personal learning project. Not company data. No real savings or impact.
A3: Ranked on Inventory_Health!W via INDEX/MATCH (Excel 2016+ compatible). Actions are text rules driven by status.
A5: Rank | B5: Row in table | C5: SKU | D5: Class | E5: Status | F5: On-hand | G5: On-order | H5: Inv. position | I5: Reorder point | J5: Days of cover | K5: Exposure EUR | L5: Data flag | M5: Recommended action
A6: 1 | B6: =MATCH(A6,Inventory_Health!$W$17:$W$56,0) -> 1 | C6: =INDEX(Inventory_Health!$A$17:$A$56,$B6) -> SKU-001 | D6: =INDEX(Inventory_Health!$B$17:$B$56,$B6) -> A | E6: =INDEX(Inventory_Health!$S$17:$S$56,$B6) -> Overstock | F6: =INDEX(Inventory_Health!$N$17:$N$56,$B6) -> 12672 | G6: =INDEX(Inventory_Health!$O$17:$O$56,$B6) -> 787 | H6: =INDEX(Inventory_Health!$P$17:$P$56,$B6) -> 13459 | I6: =INDEX(Inventory_Health!$M$17:$M$56,$B6) -> 3815.3585 | J6: =INDEX(Inventory_Health!$Q$17:$Q$56,$B6) -> 174.06593 | K6: =INDEX(Inventory_Health!$U$17:$U$56,$B6) -> 198043.2 | L6: =INDEX(Inventory_Health!$X$17:$X$56,$B6) | M6: =IF(E6="Stockout risk",IF(G6>0,"Expedite open order and add ","Place new order of ")&TEXT(ROUNDUP(I6-H6,0),"#,##0")&IF(G6>0," units if gap remains"," units"),IF(E6="Overstock",IF(G6>0,"Cancel/reduce open order; ","")&"pause replenishment until cover < "&Inputs!$B$6&" days","Monitor"))&IF(L6<>""," | Review master data ("&L6&")","") -> Cancel/reduce open order; pause replenishment until cover < 90 days
A7: 2 | B7: =MATCH(A7,Inventory_Health!$W$17:$W$56,0) -> 19 | C7: =INDEX(Inventory_Health!$A$17:$A$56,$B7) -> SKU-019 | D7: =INDEX(Inventory_Health!$B$17:$B$56,$B7) -> B | E7: =INDEX(Inventory_Health!$S$17:$S$56,$B7) -> Overstock | F7: =INDEX(Inventory_Health!$N$17:$N$56,$B7) -> 4644 | G7: =INDEX(Inventory_Health!$O$17:$O$56,$B7) -> 0 | H7: =INDEX(Inventory_Health!$P$17:$P$56,$B7) -> 4644 | I7: =INDEX(Inventory_Health!$M$17:$M$56,$B7) -> 1235.5879 | J7: =INDEX(Inventory_Health!$Q$17:$Q$56,$B7) -> 183.97284 | K7: =INDEX(Inventory_Health!$U$17:$U$56,$B7) -> 69954.493 | L7: =INDEX(Inventory_Health!$X$17:$X$56,$B7) | M7: =IF(E7="Stockout risk",IF(G7>0,"Expedite open order and add ","Place new order of ")&TEXT(ROUNDUP(I7-H7,0),"#,##0")&IF(G7>0," units if gap remains"," units"),IF(E7="Overstock",IF(G7>0,"Cancel/reduce open order; ","")&"pause replenishment until cover < "&Inputs!$B$6&" days","Monitor"))&IF(L7<>""," | Review master data ("&L7&")","") -> pause replenishment until cover < 90 days
A8: 3 | B8: =MATCH(A8,Inventory_Health!$W$17:$W$56,0) -> 15 | C8: =INDEX(Inventory_Health!$A$17:$A$56,$B8) -> SKU-015 | D8: =INDEX(Inventory_Health!$B$17:$B$56,$B8) -> B | E8: =INDEX(Inventory_Health!$S$17:$S$56,$B8) -> Overstock | F8: =INDEX(Inventory_Health!$N$17:$N$56,$B8) -> 4488 | G8: =INDEX(Inventory_Health!$O$17:$O$56,$B8) -> 0 | H8: =INDEX(Inventory_Health!$P$17:$P$56,$B8) -> 4488 | I8: =INDEX(Inventory_Health!$M$17:$M$56,$B8) -> 1080.6841 | J8: =INDEX(Inventory_Health!$Q$17:$Q$56,$B8) -> 228.14815 | K8: =INDEX(Inventory_Health!$U$17:$U$56,$B8) -> 54079.671 | L8: =INDEX(Inventory_Health!$X$17:$X$56,$B8) | M8: =IF(E8="Stockout risk",IF(G8>0,"Expedite open order and add ","Place new order of ")&TEXT(ROUNDUP(I8-H8,0),"#,##0")&IF(G8>0," units if gap remains"," units"),IF(E8="Overstock",IF(G8>0,"Cancel/reduce open order; ","")&"pause replenishment until cover < "&Inputs!$B$6&" days","Monitor"))&IF(L8<>""," | Review master data ("&L8&")","") -> pause replenishment until cover < 90 days
A9: 4 | B9: =MATCH(A9,Inventory_Health!$W$17:$W$56,0) -> 2 | C9: =INDEX(Inventory_Health!$A$17:$A$56,$B9) -> SKU-002 | D9: =INDEX(Inventory_Health!$B$17:$B$56,$B9) -> A | E9: =INDEX(Inventory_Health!$S$17:$S$56,$B9) -> Stockout risk | F9: =INDEX(Inventory_Health!$N$17:$N$56,$B9) -> 212 | G9: =INDEX(Inventory_Health!$O$17:$O$56,$B9) -> 0 | H9: =INDEX(Inventory_Health!$P$17:$P$56,$B9) -> 212 | I9: =INDEX(Inventory_Health!$M$17:$M$56,$B9) -> 1344.4568 | J9: =INDEX(Inventory_Health!$Q$17:$Q$56,$B9) -> 6.5809313 | K9: =INDEX(Inventory_Health!$U$17:$U$56,$B9) -> 41425.268 | L9: =INDEX(Inventory_Health!$X$17:$X$56,$B9) | M9: =IF(E9="Stockout risk",IF(G9>0,"Expedite open order and add ","Place new order of ")&TEXT(ROUNDUP(I9-H9,0),"#,##0")&IF(G9>0," units if gap remains"," units"),IF(E9="Overstock",IF(G9>0,"Cancel/reduce open order; ","")&"pause replenishment until cover < "&Inputs!$B$6&" days","Monitor"))&IF(L9<>""," | Review master data ("&L9&")","") -> Place new order of 1,133 units
A10: 5 | B10: =MATCH(A10,Inventory_Health!$W$17:$W$56,0) -> 4 | C10: =INDEX(Inventory_Health!$A$17:$A$56,$B10) -> SKU-004 | D10: =INDEX(Inventory_Health!$B$17:$B$56,$B10) -> A | E10: =INDEX(Inventory_Health!$S$17:$S$56,$B10) -> Stockout risk | F10: =INDEX(Inventory_Health!$N$17:$N$56,$B10) -> 643 | G10: =INDEX(Inventory_Health!$O$17:$O$56,$B10) -> 0 | H10: =INDEX(Inventory_Health!$P$17:$P$56,$B10) -> 643 | I10: =INDEX(Inventory_Health!$M$17:$M$56,$B10) -> 1850.49 | J10: =INDEX(Inventory_Health!$Q$17:$Q$56,$B10) -> 17.588902 | K10: =INDEX(Inventory_Health!$U$17:$U$56,$B10) -> 39823.02 | L10: =INDEX(Inventory_Health!$X$17:$X$56,$B10) | M10: =IF(E10="Stockout risk",IF(G10>0,"Expedite open order and add ","Place new order of ")&TEXT(ROUNDUP(I10-H10,0),"#,##0")&IF(G10>0," units if gap remains"," units"),IF(E10="Overstock",IF(G10>0,"Cancel/reduce open order; ","")&"pause replenishment until cover < "&Inputs!$B$6&" days","Monitor"))&IF(L10<>""," | Review master data ("&L10&")","") -> Place new order of 1,208 units
A11: 6 | B11: =MATCH(A11,Inventory_Health!$W$17:$W$56,0) -> 6 | C11: =INDEX(Inventory_Health!$A$17:$A$56,$B11) -> SKU-006 | D11: =INDEX(Inventory_Health!$B$17:$B$56,$B11) -> A | E11: =INDEX(Inventory_Health!$S$17:$S$56,$B11) -> Stockout risk | F11: =INDEX(Inventory_Health!$N$17:$N$56,$B11) -> 802 | G11: =INDEX(Inventory_Health!$O$17:$O$56,$B11) -> 545 | H11: =INDEX(Inventory_Health!$P$17:$P$56,$B11) -> 1347 | I11: =INDEX(Inventory_Health!$M$17:$M$56,$B11) -> 2266.983 | J11: =INDEX(Inventory_Health!$Q$17:$Q$56,$B11) -> 12.054971 | K11: =INDEX(Inventory_Health!$U$17:$U$56,$B11) -> 28629.872 | L11: =INDEX(Inventory_Health!$X$17:$X$56,$B11) | M11: =IF(E11="Stockout risk",IF(G11>0,"Expedite open order and add ","Place new order of ")&TEXT(ROUNDUP(I11-H11,0),"#,##0")&IF(G11>0," units if gap remains"," units"),IF(E11="Overstock",IF(G11>0,"Cancel/reduce open order; ","")&"pause replenishment until cover < "&Inputs!$B$6&" days","Monitor"))&IF(L11<>""," | Review master data ("&L11&")","") -> Expedite open order and add 920 units if gap remains
A12: 7 | B12: =MATCH(A12,Inventory_Health!$W$17:$W$56,0) -> 11 | C12: =INDEX(Inventory_Health!$A$17:$A$56,$B12) -> SKU-011 | D12: =INDEX(Inventory_Health!$B$17:$B$56,$B12) -> B | E12: =INDEX(Inventory_Health!$S$17:$S$56,$B12) -> Overstock | F12: =INDEX(Inventory_Health!$N$17:$N$56,$B12) -> 1611 | G12: =INDEX(Inventory_Health!$O$17:$O$56,$B12) -> 0 | H12: =INDEX(Inventory_Health!$P$17:$P$56,$B12) -> 1611 | I12: =INDEX(Inventory_Health!$M$17:$M$56,$B12) -> 480.33649 | J12: =INDEX(Inventory_Health!$Q$17:$Q$56,$B12) -> 172.96012 | K12: =INDEX(Inventory_Health!$U$17:$U$56,$B12) -> 22269.626 | L12: =INDEX(Inventory_Health!$X$17:$X$56,$B12) | M12: =IF(E12="Stockout risk",IF(G12>0,"Expedite open order and add ","Place new order of ")&TEXT(ROUNDUP(I12-H12,0),"#,##0")&IF(G12>0," units if gap remains"," units"),IF(E12="Overstock",IF(G12>0,"Cancel/reduce open order; ","")&"pause replenishment until cover < "&Inputs!$B$6&" days","Monitor"))&IF(L12<>""," | Review master data ("&L12&")","") -> pause replenishment until cover < 90 days
A13: 8 | B13: =MATCH(A13,Inventory_Health!$W$17:$W$56,0) -> 17 | C13: =INDEX(Inventory_Health!$A$17:$A$56,$B13) -> SKU-017 | D13: =INDEX(Inventory_Health!$B$17:$B$56,$B13) -> B | E13: =INDEX(Inventory_Health!$S$17:$S$56,$B13) -> Stockout risk | F13: =INDEX(Inventory_Health!$N$17:$N$56,$B13) -> 35 | G13: =INDEX(Inventory_Health!$O$17:$O$56,$B13) -> 64 | H13: =INDEX(Inventory_Health!$P$17:$P$56,$B13) -> 99 | I13: =INDEX(Inventory_Health!$M$17:$M$56,$B13) -> 302.71273 | J13: =INDEX(Inventory_Health!$Q$17:$Q$56,$B13) -> 3.5353535 | K13: =INDEX(Inventory_Health!$U$17:$U$56,$B13) -> 5708.0308 | L13: =INDEX(Inventory_Health!$X$17:$X$56,$B13) | M13: =IF(E13="Stockout risk",IF(G13>0,"Expedite open order and add ","Place new order of ")&TEXT(ROUNDUP(I13-H13,0),"#,##0")&IF(G13>0," units if gap remains"," units"),IF(E13="Overstock",IF(G13>0,"Cancel/reduce open order; ","")&"pause replenishment until cover < "&Inputs!$B$6&" days","Monitor"))&IF(L13<>""," | Review master data ("&L13&")","") -> Expedite open order and add 204 units if gap remains
A14: 9 | B14: =MATCH(A14,Inventory_Health!$W$17:$W$56,0) -> 32 | C14: =INDEX(Inventory_Health!$A$17:$A$56,$B14) -> SKU-032 | D14: =INDEX(Inventory_Health!$B$17:$B$56,$B14) -> C | E14: =INDEX(Inventory_Health!$S$17:$S$56,$B14) -> Overstock | F14: =INDEX(Inventory_Health!$N$17:$N$56,$B14) -> 1021 | G14: =INDEX(Inventory_Health!$O$17:$O$56,$B14) -> 5 | H14: =INDEX(Inventory_Health!$P$17:$P$56,$B14) -> 1026 | I14: =INDEX(Inventory_Health!$M$17:$M$56,$B14) -> 219.25378 | J14: =INDEX(Inventory_Health!$Q$17:$Q$56,$B14) -> 181.39594 | K14: =INDEX(Inventory_Health!$U$17:$U$56,$B14) -> 4141.15 | L14: =INDEX(Inventory_Health!$X$17:$X$56,$B14) -> High variability | M14: =IF(E14="Stockout risk",IF(G14>0,"Expedite open order and add ","Place new order of ")&TEXT(ROUNDUP(I14-H14,0),"#,##0")&IF(G14>0," units if gap remains"," units"),IF(E14="Overstock",IF(G14>0,"Cancel/reduce open order; ","")&"pause replenishment until cover < "&Inputs!$B$6&" days","Monitor"))&IF(L14<>""," | Review master data ("&L14&")","") -> Cancel/reduce open order; pause replenishment until cover < 90 days | Review master data (High variability)
A15: 10 | B15: =MATCH(A15,Inventory_Health!$W$17:$W$56,0) -> 26 | C15: =INDEX(Inventory_Health!$A$17:$A$56,$B15) -> SKU-026 | D15: =INDEX(Inventory_Health!$B$17:$B$56,$B15) -> C | E15: =INDEX(Inventory_Health!$S$17:$S$56,$B15) -> Overstock | F15: =INDEX(Inventory_Health!$N$17:$N$56,$B15) -> 989 | G15: =INDEX(Inventory_Health!$O$17:$O$56,$B15) -> 0 | H15: =INDEX(Inventory_Health!$P$17:$P$56,$B15) -> 989 | I15: =INDEX(Inventory_Health!$M$17:$M$56,$B15) -> 261.10498 | J15: =INDEX(Inventory_Health!$Q$17:$Q$56,$B15) -> 124.73874 | K15: =INDEX(Inventory_Health!$U$17:$U$56,$B15) -> 3503.4514 | L15: =INDEX(Inventory_Health!$X$17:$X$56,$B15) -> High variability | M15: =IF(E15="Stockout risk",IF(G15>0,"Expedite open order and add ","Place new order of ")&TEXT(ROUNDUP(I15-H15,0),"#,##0")&IF(G15>0," units if gap remains"," units"),IF(E15="Overstock",IF(G15>0,"Cancel/reduce open order; ","")&"pause replenishment until cover < "&Inputs!$B$6&" days","Monitor"))&IF(L15<>""," | Review master data ("&L15&")","") -> pause replenishment until cover < 90 days | Review master data (High variability)

Sheet LeadTime_Analysis
A1: Lead-time analysis - synthetic event log, 5 process steps
A2: SYNTHETIC DATA - personal learning project. Not company data. No real savings or impact.
A3: Timestamps = completion of each step (release time first). Durations in hours; rows failing the data-quality check are excluded from statistics.
U4: Step statistics (clean rows only)
A5: Order | B5: Release | C5: Kitting end | D5: Assembly end | E5: Test end | F5: Quality release end | G5: Handover end | H5: Kitting (h) | I5: Assembly (h) | J5: Test (h) | K5: Quality release (h) | L5: Handover (h) | M5: Data check | N5: Kitting clean (h) | O5: Assembly clean (h) | P5: Test clean (h) | Q5: Quality release clean (h) | R5: Handover clean (h) | S5: End-to-end clean (h) | U5: Step | V5: Average (h) | W5: P90 (h) | X5: Share of avg end-to-end
A6: ORD-0061 | B6: 46083.319 | C6: 46083.599 | D6: 46084.74 | E6: 46085.473 | F6: 46085.773 | G6: 46085.905 | H6: =IF(OR(B6="",C6=""),"",(C6-B6)*24) -> 6.7 | I6: =IF(OR(C6="",D6=""),"",(D6-C6)*24) -> 27.4 | J6: =IF(OR(D6="",E6=""),"",(E6-D6)*24) -> 17.583333 | K6: =IF(OR(E6="",F6=""),"",(F6-E6)*24) -> 7.2 | L6: =IF(OR(F6="",G6=""),"",(G6-F6)*24) -> 3.1666667 | M6: =IF(COUNT(B6:G6)<6,"Missing timestamp",IF(MIN(H6:L6)<0,"Negative duration","OK")) -> OK | N6: =IF($M6="OK",H6,"") -> 6.7 | O6: =IF($M6="OK",I6,"") -> 27.4 | P6: =IF($M6="OK",J6,"") -> 17.583333 | Q6: =IF($M6="OK",K6,"") -> 7.2 | R6: =IF($M6="OK",L6,"") -> 3.1666667 | S6: =IF(M6="OK",SUM(N6:R6),"") -> 62.05 | U6: Kitting | V6: =AVERAGE($N$6:$N$205) -> 5.9069231 | W6: =PERCENTILE($N$6:$N$205,0.9) -> 9.0166667 | X6: =V6/$V$11 -> 0.10650732
A7: ORD-0023 | B7: 46084.113 | C7: 46084.362 | D7: 46085.368 | E7: 46086.394 | F7: 46086.575 | G7: 46086.628 | H7: =IF(OR(B7="",C7=""),"",(C7-B7)*24) -> 5.9666667 | I7: =IF(OR(C7="",D7=""),"",(D7-C7)*24) -> 24.15 | J7: =IF(OR(D7="",E7=""),"",(E7-D7)*24) -> 24.616667 | K7: =IF(OR(E7="",F7=""),"",(F7-E7)*24) -> 4.35 | L7: =IF(OR(F7="",G7=""),"",(G7-F7)*24) -> 1.2833333 | M7: =IF(COUNT(B7:G7)<6,"Missing timestamp",IF(MIN(H7:L7)<0,"Negative duration","OK")) -> OK | N7: =IF($M7="OK",H7,"") -> 5.9666667 | O7: =IF($M7="OK",I7,"") -> 24.15 | P7: =IF($M7="OK",J7,"") -> 24.616667 | Q7: =IF($M7="OK",K7,"") -> 4.35 | R7: =IF($M7="OK",L7,"") -> 1.2833333 | S7: =IF(M7="OK",SUM(N7:R7),"") -> 60.366667 | U7: Assembly | V7: =AVERAGE($O$6:$O$205) -> 20.176154 | W7: =PERCENTILE($O$6:$O$205,0.9) -> 27.366667 | X7: =V7/$V$11 -> 0.36379482
A8: ORD-0089 | B8: 46084.248 | C8: 46084.478 | D8: 46085.757 | E8: 46086.594 | F8: 46087.106 | G8: 46087.287 | H8: =IF(OR(B8="",C8=""),"",(C8-B8)*24) -> 5.5166667 | I8: =IF(OR(C8="",D8=""),"",(D8-C8)*24) -> 30.7 | J8: =IF(OR(D8="",E8=""),"",(E8-D8)*24) -> 20.1 | K8: =IF(OR(E8="",F8=""),"",(F8-E8)*24) -> 12.266667 | L8: =IF(OR(F8="",G8=""),"",(G8-F8)*24) -> 4.35 | M8: =IF(COUNT(B8:G8)<6,"Missing timestamp",IF(MIN(H8:L8)<0,"Negative duration","OK")) -> OK | N8: =IF($M8="OK",H8,"") -> 5.5166667 | O8: =IF($M8="OK",I8,"") -> 30.7 | P8: =IF($M8="OK",J8,"") -> 20.1 | Q8: =IF($M8="OK",K8,"") -> 12.266667 | R8: =IF($M8="OK",L8,"") -> 4.35 | S8: =IF(M8="OK",SUM(N8:R8),"") -> 72.933333 | U8: Test | V8: =AVERAGE($P$6:$P$205) -> 17.673504 | W8: =PERCENTILE($P$6:$P$205,0.9) -> 33.866667 | X8: =V8/$V$11 -> 0.31866972
A9: ORD-0200 | B9: 46084.391 | C9: 46084.849 | D9: 46085.544 | E9: 46086.262 | F9: 46086.784 | G9: 46086.895 | H9: =IF(OR(B9="",C9=""),"",(C9-B9)*24) -> 10.983333 | I9: =IF(OR(C9="",D9=""),"",(D9-C9)*24) -> 16.683333 | J9: =IF(OR(D9="",E9=""),"",(E9-D9)*24) -> 17.25 | K9: =IF(OR(E9="",F9=""),"",(F9-E9)*24) -> 12.516667 | L9: =IF(OR(F9="",G9=""),"",(G9-F9)*24) -> 2.6666667 | M9: =IF(COUNT(B9:G9)<6,"Missing timestamp",IF(MIN(H9:L9)<0,"Negative duration","OK")) -> OK | N9: =IF($M9="OK",H9,"") -> 10.983333 | O9: =IF($M9="OK",I9,"") -> 16.683333 | P9: =IF($M9="OK",J9,"") -> 17.25 | Q9: =IF($M9="OK",K9,"") -> 12.516667 | R9: =IF($M9="OK",L9,"") -> 2.6666667 | S9: =IF(M9="OK",SUM(N9:R9),"") -> 60.1 | U9: Quality release | V9: =AVERAGE($Q$6:$Q$205) -> 8.7366667 | W9: =PERCENTILE($Q$6:$Q$205,0.9) -> 13.513333 | X9: =V9/$V$11 -> 0.15753022
A10: ORD-0004 | B10: 46084.493 | C10: 46084.906 | D10: 46086.618 | E10: 46087.085 | F10: 46087.244 | G10: 46087.35 | H10: =IF(OR(B10="",C10=""),"",(C10-B10)*24) -> 9.9166667 | I10: =IF(OR(C10="",D10=""),"",(D10-C10)*24) -> 41.083333 | J10: =IF(OR(D10="",E10=""),"",(E10-D10)*24) -> 11.2 | K10: =IF(OR(E10="",F10=""),"",(F10-E10)*24) -> 3.8333333 | L10: =IF(OR(F10="",G10=""),"",(G10-F10)*24) -> 2.5333333 | M10: =IF(COUNT(B10:G10)<6,"Missing timestamp",IF(MIN(H10:L10)<0,"Negative duration","OK")) -> OK | N10: =IF($M10="OK",H10,"") -> 9.9166667 | O10: =IF($M10="OK",I10,"") -> 41.083333 | P10: =IF($M10="OK",J10,"") -> 11.2 | Q10: =IF($M10="OK",K10,"") -> 3.8333333 | R10: =IF($M10="OK",L10,"") -> 2.5333333 | S10: =IF(M10="OK",SUM(N10:R10),"") -> 68.566667 | U10: Handover | V10: =AVERAGE($R$6:$R$205) -> 2.9670085 | W10: =PERCENTILE($R$6:$R$205,0.9) -> 4.4266667 | X10: =V10/$V$11 -> 0.053497923
A11: ORD-0151 | B11: 46084.572 | C11: 46084.773 | D11: 46085.101 | E11: 46085.372 | F11: 46085.913 | G11: 46086.006 | H11: =IF(OR(B11="",C11=""),"",(C11-B11)*24) -> 4.8333333 | I11: =IF(OR(C11="",D11=""),"",(D11-C11)*24) -> 7.8833333 | J11: =IF(OR(D11="",E11=""),"",(E11-D11)*24) -> 6.4833333 | K11: =IF(OR(E11="",F11=""),"",(F11-E11)*24) -> 13 | L11: =IF(OR(F11="",G11=""),"",(G11-F11)*24) -> 2.2333333 | M11: =IF(COUNT(B11:G11)<6,"Missing timestamp",IF(MIN(H11:L11)<0,"Negative duration","OK")) -> OK | N11: =IF($M11="OK",H11,"") -> 4.8333333 | O11: =IF($M11="OK",I11,"") -> 7.8833333 | P11: =IF($M11="OK",J11,"") -> 6.4833333 | Q11: =IF($M11="OK",K11,"") -> 13 | R11: =IF($M11="OK",L11,"") -> 2.2333333 | S11: =IF(M11="OK",SUM(N11:R11),"") -> 34.433333 | U11: End-to-end | V11: =AVERAGE($S$6:$S$205) -> 55.460256 | W11: =PERCENTILE($S$6:$S$205,0.9) -> 73.863333 | X11: =SUM(X6:X10) -> 1
A12: ORD-0037 | B12: 46084.727 | C12: 46084.984 | D12: 46085.669 | E12: 46086.072 | F12: 46086.465 | G12: 46086.567 | H12: =IF(OR(B12="",C12=""),"",(C12-B12)*24) -> 6.1666667 | I12: =IF(OR(C12="",D12=""),"",(D12-C12)*24) -> 16.433333 | J12: =IF(OR(D12="",E12=""),"",(E12-D12)*24) -> 9.6833333 | K12: =IF(OR(E12="",F12=""),"",(F12-E12)*24) -> 9.4166667 | L12: =IF(OR(F12="",G12=""),"",(G12-F12)*24) -> 2.45 | M12: =IF(COUNT(B12:G12)<6,"Missing timestamp",IF(MIN(H12:L12)<0,"Negative duration","OK")) -> OK | N12: =IF($M12="OK",H12,"") -> 6.1666667 | O12: =IF($M12="OK",I12,"") -> 16.433333 | P12: =IF($M12="OK",J12,"") -> 9.6833333 | Q12: =IF($M12="OK",K12,"") -> 9.4166667 | R12: =IF($M12="OK",L12,"") -> 2.45 | S12: =IF(M12="OK",SUM(N12:R12),"") -> 44.15
A13: ORD-0070 | B13: 46084.94 | C13: 46085.335 | D13: 46086.699 | E13: 46088.126 | F13: 46088.458 | G13: 46088.591 | H13: =IF(OR(B13="",C13=""),"",(C13-B13)*24) -> 9.4666667 | I13: =IF(OR(C13="",D13=""),"",(D13-C13)*24) -> 32.75 | J13: =IF(OR(D13="",E13=""),"",(E13-D13)*24) -> 34.25 | K13: =IF(OR(E13="",F13=""),"",(F13-E13)*24) -> 7.95 | L13: =IF(OR(F13="",G13=""),"",(G13-F13)*24) -> 3.2 | M13: =IF(COUNT(B13:G13)<6,"Missing timestamp",IF(MIN(H13:L13)<0,"Negative duration","OK")) -> OK | N13: =IF($M13="OK",H13,"") -> 9.4666667 | O13: =IF($M13="OK",I13,"") -> 32.75 | P13: =IF($M13="OK",J13,"") -> 34.25 | Q13: =IF($M13="OK",K13,"") -> 7.95 | R13: =IF($M13="OK",L13,"") -> 3.2 | S13: =IF(M13="OK",SUM(N13:R13),"") -> 87.616667 | U13: Bottleneck step (highest average) | V13: =INDEX(U6:U10,MATCH(MAX(V6:V10),V6:V10,0)) -> Assembly
A14: ORD-0099 | B14: 46085.095 | C14: 46085.346 | D14: 46086.409 | E14: 46087.134 | F14: 46087.41 | G14: 46087.56 | H14: =IF(OR(B14="",C14=""),"",(C14-B14)*24) -> 6.0166667 | I14: =IF(OR(C14="",D14=""),"",(D14-C14)*24) -> 25.516667 | J14: =IF(OR(D14="",E14=""),"",(E14-D14)*24) -> 17.4 | K14: =IF(OR(E14="",F14=""),"",(F14-E14)*24) -> 6.6333333 | L14: =IF(OR(F14="",G14=""),"",(G14-F14)*24) -> 3.6 | M14: =IF(COUNT(B14:G14)<6,"Missing timestamp",IF(MIN(H14:L14)<0,"Negative duration","OK")) -> OK | N14: =IF($M14="OK",H14,"") -> 6.0166667 | O14: =IF($M14="OK",I14,"") -> 25.516667 | P14: =IF($M14="OK",J14,"") -> 17.4 | Q14: =IF($M14="OK",K14,"") -> 6.6333333 | R14: =IF($M14="OK",L14,"") -> 3.6 | S14: =IF(M14="OK",SUM(N14:R14),"") -> 59.166667 | U14: Bottleneck step (highest P90) | V14: =INDEX(U6:U10,MATCH(MAX(W6:W10),W6:W10,0)) -> Test
A15: ORD-0017 | B15: 46085.245 | C15: 46085.409 | D15: 46086.192 | E15: 46087.393 | F15: 46087.627 | G15: 46087.713 | H15: =IF(OR(B15="",C15=""),"",(C15-B15)*24) -> 3.9333333 | I15: =IF(OR(C15="",D15=""),"",(D15-C15)*24) -> 18.8 | J15: =IF(OR(D15="",E15=""),"",(E15-D15)*24) -> 28.816667 | K15: =IF(OR(E15="",F15=""),"",(F15-E15)*24) -> 5.6166667 | L15: =IF(OR(F15="",G15=""),"",(G15-F15)*24) -> 2.05 | M15: =IF(COUNT(B15:G15)<6,"Missing timestamp",IF(MIN(H15:L15)<0,"Negative duration","OK")) -> OK | N15: =IF($M15="OK",H15,"") -> 3.9333333 | O15: =IF($M15="OK",I15,"") -> 18.8 | P15: =IF($M15="OK",J15,"") -> 28.816667 | Q15: =IF($M15="OK",K15,"") -> 5.6166667 | R15: =IF($M15="OK",L15,"") -> 2.05 | S15: =IF(M15="OK",SUM(N15:R15),"") -> 59.216667 | U15: Longest-step average (h) | V15: =MAX(V6:V10) -> 20.176154
A16: ORD-0018 | B16: 46085.39 | C16: 46085.676 | D16: 46086.422 | E16: 46087.347 | F16: 46087.691 | G16: 46087.841 | H16: =IF(OR(B16="",C16=""),"",(C16-B16)*24) -> 6.8666667 | I16: =IF(OR(C16="",D16=""),"",(D16-C16)*24) -> 17.883333 | J16: =IF(OR(D16="",E16=""),"",(E16-D16)*24) -> 22.2 | K16: =IF(OR(E16="",F16=""),"",(F16-E16)*24) -> 8.2666667 | L16: =IF(OR(F16="",G16=""),"",(G16-F16)*24) -> 3.6 | M16: =IF(COUNT(B16:G16)<6,"Missing timestamp",IF(MIN(H16:L16)<0,"Negative duration","OK")) -> OK | N16: =IF($M16="OK",H16,"") -> 6.8666667 | O16: =IF($M16="OK",I16,"") -> 17.883333 | P16: =IF($M16="OK",J16,"") -> 22.2 | Q16: =IF($M16="OK",K16,"") -> 8.2666667 | R16: =IF($M16="OK",L16,"") -> 3.6 | S16: =IF(M16="OK",SUM(N16:R16),"") -> 58.816667
A17: ORD-0122 | B17: 46085.458 | C17: 46085.648 | D17: 46086.943 | E17: 46087.713 | F17: 46088.03 | G17: 46088.208 | H17: =IF(OR(B17="",C17=""),"",(C17-B17)*24) -> 4.5666667 | I17: =IF(OR(C17="",D17=""),"",(D17-C17)*24) -> 31.083333 | J17: =IF(OR(D17="",E17=""),"",(E17-D17)*24) -> 18.466667 | K17: =IF(OR(E17="",F17=""),"",(F17-E17)*24) -> 7.6166667 | L17: =IF(OR(F17="",G17=""),"",(G17-F17)*24) -> 4.2833333 | M17: =IF(COUNT(B17:G17)<6,"Missing timestamp",IF(MIN(H17:L17)<0,"Negative duration","OK")) -> OK | N17: =IF($M17="OK",H17,"") -> 4.5666667 | O17: =IF($M17="OK",I17,"") -> 31.083333 | P17: =IF($M17="OK",J17,"") -> 18.466667 | Q17: =IF($M17="OK",K17,"") -> 7.6166667 | R17: =IF($M17="OK",L17,"") -> 4.2833333 | S17: =IF(M17="OK",SUM(N17:R17),"") -> 66.016667 | U17: Data-quality check
A18: ORD-0108 | B18: 46085.748 | C18: 46085.91 | D18: 46086.446 | E18: 46086.888 | F18: 46087.298 | G18: 46087.411 | H18: =IF(OR(B18="",C18=""),"",(C18-B18)*24) -> 3.9 | I18: =IF(OR(C18="",D18=""),"",(D18-C18)*24) -> 12.85 | J18: =IF(OR(D18="",E18=""),"",(E18-D18)*24) -> 10.616667 | K18: =IF(OR(E18="",F18=""),"",(F18-E18)*24) -> 9.8333333 | L18: =IF(OR(F18="",G18=""),"",(G18-F18)*24) -> 2.7166667 | M18: =IF(COUNT(B18:G18)<6,"Missing timestamp",IF(MIN(H18:L18)<0,"Negative duration","OK")) -> OK | N18: =IF($M18="OK",H18,"") -> 3.9 | O18: =IF($M18="OK",I18,"") -> 12.85 | P18: =IF($M18="OK",J18,"") -> 10.616667 | Q18: =IF($M18="OK",K18,"") -> 9.8333333 | R18: =IF($M18="OK",L18,"") -> 2.7166667 | S18: =IF(M18="OK",SUM(N18:R18),"") -> 39.916667 | U18: Orders in log | V18: =COUNTA($A$6:$A$205) -> 200
A19: ORD-0113 | B19: 46085.867 | C19: 46086.06 | D19: 46087.002 | E19: 46087.879 | F19: 46088.157 | G19: 46088.236 | H19: =IF(OR(B19="",C19=""),"",(C19-B19)*24) -> 4.6166667 | I19: =IF(OR(C19="",D19=""),"",(D19-C19)*24) -> 22.616667 | J19: =IF(OR(D19="",E19=""),"",(E19-D19)*24) -> 21.05 | K19: =IF(OR(E19="",F19=""),"",(F19-E19)*24) -> 6.6666667 | L19: =IF(OR(F19="",G19=""),"",(G19-F19)*24) -> 1.9 | M19: =IF(COUNT(B19:G19)<6,"Missing timestamp",IF(MIN(H19:L19)<0,"Negative duration","OK")) -> OK | N19: =IF($M19="OK",H19,"") -> 4.6166667 | O19: =IF($M19="OK",I19,"") -> 22.616667 | P19: =IF($M19="OK",J19,"") -> 21.05 | Q19: =IF($M19="OK",K19,"") -> 6.6666667 | R19: =IF($M19="OK",L19,"") -> 1.9 | S19: =IF(M19="OK",SUM(N19:R19),"") -> 56.85 | U19: OK (used in statistics) | V19: =COUNTIF($M$6:$M$205,"OK") -> 195
A20: ORD-0077 | B20: 46085.943 | C20: 46086.299 | D20: 46087.146 | E20: 46087.585 | F20: 46088.005 | G20: 46088.103 | H20: =IF(OR(B20="",C20=""),"",(C20-B20)*24) -> 8.55 | I20: =IF(OR(C20="",D20=""),"",(D20-C20)*24) -> 20.316667 | J20: =IF(OR(D20="",E20=""),"",(E20-D20)*24) -> 10.533333 | K20: =IF(OR(E20="",F20=""),"",(F20-E20)*24) -> 10.083333 | L20: =IF(OR(F20="",G20=""),"",(G20-F20)*24) -> 2.35 | M20: =IF(COUNT(B20:G20)<6,"Missing timestamp",IF(MIN(H20:L20)<0,"Negative duration","OK")) -> OK | N20: =IF($M20="OK",H20,"") -> 8.55 | O20: =IF($M20="OK",I20,"") -> 20.316667 | P20: =IF($M20="OK",J20,"") -> 10.533333 | Q20: =IF($M20="OK",K20,"") -> 10.083333 | R20: =IF($M20="OK",L20,"") -> 2.35 | S20: =IF(M20="OK",SUM(N20:R20),"") -> 51.833333 | U20: Flagged: missing timestamp | V20: =COUNTIF($M$6:$M$205,"Missing timestamp") -> 3
A21: ORD-0134 | B21: 46086.64 | C21: 46086.915 | D21: 46087.595 | E21: 46087.906 | F21: 46088.778 | G21: 46088.91 | H21: =IF(OR(B21="",C21=""),"",(C21-B21)*24) -> 6.5833333 | I21: =IF(OR(C21="",D21=""),"",(D21-C21)*24) -> 16.333333 | J21: =IF(OR(D21="",E21=""),"",(E21-D21)*24) -> 7.45 | K21: =IF(OR(E21="",F21=""),"",(F21-E21)*24) -> 20.933333 | L21: =IF(OR(F21="",G21=""),"",(G21-F21)*24) -> 3.1666667 | M21: =IF(COUNT(B21:G21)<6,"Missing timestamp",IF(MIN(H21:L21)<0,"Negative duration","OK")) -> OK | N21: =IF($M21="OK",H21,"") -> 6.5833333 | O21: =IF($M21="OK",I21,"") -> 16.333333 | P21: =IF($M21="OK",J21,"") -> 7.45 | Q21: =IF($M21="OK",K21,"") -> 20.933333 | R21: =IF($M21="OK",L21,"") -> 3.1666667 | S21: =IF(M21="OK",SUM(N21:R21),"") -> 54.466667 | U21: Flagged: negative duration | V21: =COUNTIF($M$6:$M$205,"Negative duration") -> 2
A22: ORD-0181 | B22: 46086.903 | C22: 46087.252 | D22: 46088.416 | E22: 46088.657 | F22: 46088.963 | G22: 46089.151 | H22: =IF(OR(B22="",C22=""),"",(C22-B22)*24) -> 8.3833333 | I22: =IF(OR(C22="",D22=""),"",(D22-C22)*24) -> 27.933333 | J22: =IF(OR(D22="",E22=""),"",(E22-D22)*24) -> 5.7833333 | K22: =IF(OR(E22="",F22=""),"",(F22-E22)*24) -> 7.3333333 | L22: =IF(OR(F22="",G22=""),"",(G22-F22)*24) -> 4.5333333 | M22: =IF(COUNT(B22:G22)<6,"Missing timestamp",IF(MIN(H22:L22)<0,"Negative duration","OK")) -> OK | N22: =IF($M22="OK",H22,"") -> 8.3833333 | O22: =IF($M22="OK",I22,"") -> 27.933333 | P22: =IF($M22="OK",J22,"") -> 5.7833333 | Q22: =IF($M22="OK",K22,"") -> 7.3333333 | R22: =IF($M22="OK",L22,"") -> 4.5333333 | S22: =IF(M22="OK",SUM(N22:R22),"") -> 53.966667 | U22: Share of usable records | V22: =V19/V18 -> 0.975
A23: ORD-0094 | B23: 46087.285 | C23: 46087.466 | D23: 46088.208 | E23: 46088.747 | F23: 46089.058 | G23: 46089.276 | H23: =IF(OR(B23="",C23=""),"",(C23-B23)*24) -> 4.3333333 | I23: =IF(OR(C23="",D23=""),"",(D23-C23)*24) -> 17.816667 | J23: =IF(OR(D23="",E23=""),"",(E23-D23)*24) -> 12.933333 | K23: =IF(OR(E23="",F23=""),"",(F23-E23)*24) -> 7.45 | L23: =IF(OR(F23="",G23=""),"",(G23-F23)*24) -> 5.25 | M23: =IF(COUNT(B23:G23)<6,"Missing timestamp",IF(MIN(H23:L23)<0,"Negative duration","OK")) -> OK | N23: =IF($M23="OK",H23,"") -> 4.3333333 | O23: =IF($M23="OK",I23,"") -> 17.816667 | P23: =IF($M23="OK",J23,"") -> 12.933333 | Q23: =IF($M23="OK",K23,"") -> 7.45 | R23: =IF($M23="OK",L23,"") -> 5.25 | S23: =IF(M23="OK",SUM(N23:R23),"") -> 47.783333
A24: ORD-0112 | B24: 46087.76 | C24: 46088.13 | D24: 46089.031 | E24: 46090.041 | F24: 46090.283 | G24: 46090.424 | H24: =IF(OR(B24="",C24=""),"",(C24-B24)*24) -> 8.8666667 | I24: =IF(OR(C24="",D24=""),"",(D24-C24)*24) -> 21.633333 | J24: =IF(OR(D24="",E24=""),"",(E24-D24)*24) -> 24.233333 | K24: =IF(OR(E24="",F24=""),"",(F24-E24)*24) -> 5.8 | L24: =IF(OR(F24="",G24=""),"",(G24-F24)*24) -> 3.3833333 | M24: =IF(COUNT(B24:G24)<6,"Missing timestamp",IF(MIN(H24:L24)<0,"Negative duration","OK")) -> OK | N24: =IF($M24="OK",H24,"") -> 8.8666667 | O24: =IF($M24="OK",I24,"") -> 21.633333 | P24: =IF($M24="OK",J24,"") -> 24.233333 | Q24: =IF($M24="OK",K24,"") -> 5.8 | R24: =IF($M24="OK",L24,"") -> 3.3833333 | S24: =IF(M24="OK",SUM(N24:R24),"") -> 63.916667
A25: ORD-0170 | B25: 46087.813 | C25: 46088.028 | D25: 46089.053 | E25: 46089.761 | F25: 46090.093 | G25: 46090.283 | H25: =IF(OR(B25="",C25=""),"",(C25-B25)*24) -> 5.15 | I25: =IF(OR(C25="",D25=""),"",(D25-C25)*24) -> 24.6 | J25: =IF(OR(D25="",E25=""),"",(E25-D25)*24) -> 17 | K25: =IF(OR(E25="",F25=""),"",(F25-E25)*24) -> 7.9666667 | L25: =IF(OR(F25="",G25=""),"",(G25-F25)*24) -> 4.55 | M25: =IF(COUNT(B25:G25)<6,"Missing timestamp",IF(MIN(H25:L25)<0,"Negative duration","OK")) -> OK | N25: =IF($M25="OK",H25,"") -> 5.15 | O25: =IF($M25="OK",I25,"") -> 24.6 | P25: =IF($M25="OK",J25,"") -> 17 | Q25: =IF($M25="OK",K25,"") -> 7.9666667 | R25: =IF($M25="OK",L25,"") -> 4.55 | S25: =IF(M25="OK",SUM(N25:R25),"") -> 59.266667
A26: ORD-0050 | B26: 46087.899 | C26: 46088.226 | D26: 46088.797 | E26: 46089.081 | F26: 46089.304 | G26: 46089.434 | H26: =IF(OR(B26="",C26=""),"",(C26-B26)*24) -> 7.8666667 | I26: =IF(OR(C26="",D26=""),"",(D26-C26)*24) -> 13.7 | J26: =IF(OR(D26="",E26=""),"",(E26-D26)*24) -> 6.8 | K26: =IF(OR(E26="",F26=""),"",(F26-E26)*24) -> 5.3666667 | L26: =IF(OR(F26="",G26=""),"",(G26-F26)*24) -> 3.1166667 | M26: =IF(COUNT(B26:G26)<6,"Missing timestamp",IF(MIN(H26:L26)<0,"Negative duration","OK")) -> OK | N26: =IF($M26="OK",H26,"") -> 7.8666667 | O26: =IF($M26="OK",I26,"") -> 13.7 | P26: =IF($M26="OK",J26,"") -> 6.8 | Q26: =IF($M26="OK",K26,"") -> 5.3666667 | R26: =IF($M26="OK",L26,"") -> 3.1166667 | S26: =IF(M26="OK",SUM(N26:R26),"") -> 36.85
A27: ORD-0005 | B27: 46088.061 | C27: 46088.281 | D27: 46088.851 | E27: 46089.736 | F27: 46090.163 | G27: 46090.233 | H27: =IF(OR(B27="",C27=""),"",(C27-B27)*24) -> 5.2833333 | I27: =IF(OR(C27="",D27=""),"",(D27-C27)*24) -> 13.683333 | J27: =IF(OR(D27="",E27=""),"",(E27-D27)*24) -> 21.233333 | K27: =IF(OR(E27="",F27=""),"",(F27-E27)*24) -> 10.25 | L27: =IF(OR(F27="",G27=""),"",(G27-F27)*24) -> 1.6666667 | M27: =IF(COUNT(B27:G27)<6,"Missing timestamp",IF(MIN(H27:L27)<0,"Negative duration","OK")) -> OK | N27: =IF($M27="OK",H27,"") -> 5.2833333 | O27: =IF($M27="OK",I27,"") -> 13.683333 | P27: =IF($M27="OK",J27,"") -> 21.233333 | Q27: =IF($M27="OK",K27,"") -> 10.25 | R27: =IF($M27="OK",L27,"") -> 1.6666667 | S27: =IF(M27="OK",SUM(N27:R27),"") -> 52.116667
A28: ORD-0007 | B28: 46088.262 | C28: 46088.39 | D28: 46089.227 | E28: 46089.698 | F28: 46090.423 | G28: 46090.533 | H28: =IF(OR(B28="",C28=""),"",(C28-B28)*24) -> 3.0833333 | I28: =IF(OR(C28="",D28=""),"",(D28-C28)*24) -> 20.083333 | J28: =IF(OR(D28="",E28=""),"",(E28-D28)*24) -> 11.3 | K28: =IF(OR(E28="",F28=""),"",(F28-E28)*24) -> 17.4 | L28: =IF(OR(F28="",G28=""),"",(G28-F28)*24) -> 2.65 | M28: =IF(COUNT(B28:G28)<6,"Missing timestamp",IF(MIN(H28:L28)<0,"Negative duration","OK")) -> OK | N28: =IF($M28="OK",H28,"") -> 3.0833333 | O28: =IF($M28="OK",I28,"") -> 20.083333 | P28: =IF($M28="OK",J28,"") -> 11.3 | Q28: =IF($M28="OK",K28,"") -> 17.4 | R28: =IF($M28="OK",L28,"") -> 2.65 | S28: =IF(M28="OK",SUM(N28:R28),"") -> 54.516667
A29: ORD-0060 | B29: 46088.528 | C29: 46088.685 | D29: 46089.46 | E29: 46090.579 | F29: 46091.069 | G29: 46091.195 | H29: =IF(OR(B29="",C29=""),"",(C29-B29)*24) -> 3.7666667 | I29: =IF(OR(C29="",D29=""),"",(D29-C29)*24) -> 18.616667 | J29: =IF(OR(D29="",E29=""),"",(E29-D29)*24) -> 26.85 | K29: =IF(OR(E29="",F29=""),"",(F29-E29)*24) -> 11.75 | L29: =IF(OR(F29="",G29=""),"",(G29-F29)*24) -> 3.0333333 | M29: =IF(COUNT(B29:G29)<6,"Missing timestamp",IF(MIN(H29:L29)<0,"Negative duration","OK")) -> OK | N29: =IF($M29="OK",H29,"") -> 3.7666667 | O29: =IF($M29="OK",I29,"") -> 18.616667 | P29: =IF($M29="OK",J29,"") -> 26.85 | Q29: =IF($M29="OK",K29,"") -> 11.75 | R29: =IF($M29="OK",L29,"") -> 3.0333333 | S29: =IF(M29="OK",SUM(N29:R29),"") -> 64.016667
A30: ORD-0139 | B30: 46088.604 | C30: 46088.742 | D30: 46089.764 | E30: 46090.554 | F30: 46090.736 | G30: 46090.853 | H30: =IF(OR(B30="",C30=""),"",(C30-B30)*24) -> 3.3166667 | I30: =IF(OR(C30="",D30=""),"",(D30-C30)*24) -> 24.516667 | J30: =IF(OR(D30="",E30=""),"",(E30-D30)*24) -> 18.966667 | K30: =IF(OR(E30="",F30=""),"",(F30-E30)*24) -> 4.3666667 | L30: =IF(OR(F30="",G30=""),"",(G30-F30)*24) -> 2.8 | M30: =IF(COUNT(B30:G30)<6,"Missing timestamp",IF(MIN(H30:L30)<0,"Negative duration","OK")) -> OK | N30: =IF($M30="OK",H30,"") -> 3.3166667 | O30: =IF($M30="OK",I30,"") -> 24.516667 | P30: =IF($M30="OK",J30,"") -> 18.966667 | Q30: =IF($M30="OK",K30,"") -> 4.3666667 | R30: =IF($M30="OK",L30,"") -> 2.8 | S30: =IF(M30="OK",SUM(N30:R30),"") -> 53.966667
A31: ORD-0188 | B31: 46088.638 | C31: 46088.857 | D31: 46089.369 | E31: 46090.212 | F31: 46090.344 | G31: 46090.491 | H31: =IF(OR(B31="",C31=""),"",(C31-B31)*24) -> 5.25 | I31: =IF(OR(C31="",D31=""),"",(D31-C31)*24) -> 12.3 | J31: =IF(OR(D31="",E31=""),"",(E31-D31)*24) -> 20.216667 | K31: =IF(OR(E31="",F31=""),"",(F31-E31)*24) -> 3.1666667 | L31: =IF(OR(F31="",G31=""),"",(G31-F31)*24) -> 3.5333333 | M31: =IF(COUNT(B31:G31)<6,"Missing timestamp",IF(MIN(H31:L31)<0,"Negative duration","OK")) -> OK | N31: =IF($M31="OK",H31,"") -> 5.25 | O31: =IF($M31="OK",I31,"") -> 12.3 | P31: =IF($M31="OK",J31,"") -> 20.216667 | Q31: =IF($M31="OK",K31,"") -> 3.1666667 | R31: =IF($M31="OK",L31,"") -> 3.5333333 | S31: =IF(M31="OK",SUM(N31:R31),"") -> 44.466667
A32: ORD-0073 | B32: 46088.764 | C32: 46089.07 | D32: 46089.963 | E32: 46090.235 | F32: 46090.851 | G32: 46090.95 | H32: =IF(OR(B32="",C32=""),"",(C32-B32)*24) -> 7.35 | I32: =IF(OR(C32="",D32=""),"",(D32-C32)*24) -> 21.416667 | J32: =IF(OR(D32="",E32=""),"",(E32-D32)*24) -> 6.5333333 | K32: =IF(OR(E32="",F32=""),"",(F32-E32)*24) -> 14.8 | L32: =IF(OR(F32="",G32=""),"",(G32-F32)*24) -> 2.3666667 | M32: =IF(COUNT(B32:G32)<6,"Missing timestamp",IF(MIN(H32:L32)<0,"Negative duration","OK")) -> OK | N32: =IF($M32="OK",H32,"") -> 7.35 | O32: =IF($M32="OK",I32,"") -> 21.416667 | P32: =IF($M32="OK",J32,"") -> 6.5333333 | Q32: =IF($M32="OK",K32,"") -> 14.8 | R32: =IF($M32="OK",L32,"") -> 2.3666667 | S32: =IF(M32="OK",SUM(N32:R32),"") -> 52.466667
A33: ORD-0076 | B33: 46089.073 | C33: 46089.185 | D33: 46089.899 | E33: 46090.047 | F33: 46090.398 | G33: 46090.515 | H33: =IF(OR(B33="",C33=""),"",(C33-B33)*24) -> 2.7 | I33: =IF(OR(C33="",D33=""),"",(D33-C33)*24) -> 17.133333 | J33: =IF(OR(D33="",E33=""),"",(E33-D33)*24) -> 3.5333333 | K33: =IF(OR(E33="",F33=""),"",(F33-E33)*24) -> 8.4333333 | L33: =IF(OR(F33="",G33=""),"",(G33-F33)*24) -> 2.8166667 | M33: =IF(COUNT(B33:G33)<6,"Missing timestamp",IF(MIN(H33:L33)<0,"Negative duration","OK")) -> OK | N33: =IF($M33="OK",H33,"") -> 2.7 | O33: =IF($M33="OK",I33,"") -> 17.133333 | P33: =IF($M33="OK",J33,"") -> 3.5333333 | Q33: =IF($M33="OK",K33,"") -> 8.4333333 | R33: =IF($M33="OK",L33,"") -> 2.8166667 | S33: =IF(M33="OK",SUM(N33:R33),"") -> 34.616667
A34: ORD-0071 | B34: 46089.529 | C34: 46089.774 | D34: 46090.603 | E34: 46091.64 | F34: 46091.978 | G34: 46092.069 | H34: =IF(OR(B34="",C34=""),"",(C34-B34)*24) -> 5.8833333 | I34: =IF(OR(C34="",D34=""),"",(D34-C34)*24) -> 19.883333 | J34: =IF(OR(D34="",E34=""),"",(E34-D34)*24) -> 24.9 | K34: =IF(OR(E34="",F34=""),"",(F34-E34)*24) -> 8.1166667 | L34: =IF(OR(F34="",G34=""),"",(G34-F34)*24) -> 2.1833333 | M34: =IF(COUNT(B34:G34)<6,"Missing timestamp",IF(MIN(H34:L34)<0,"Negative duration","OK")) -> OK | N34: =IF($M34="OK",H34,"") -> 5.8833333 | O34: =IF($M34="OK",I34,"") -> 19.883333 | P34: =IF($M34="OK",J34,"") -> 24.9 | Q34: =IF($M34="OK",K34,"") -> 8.1166667 | R34: =IF($M34="OK",L34,"") -> 2.1833333 | S34: =IF(M34="OK",SUM(N34:R34),"") -> 60.966667
... A64: ORD-0195 | B64: 46095.603 | C64: 46095.786 | D64: 46096.519 | E64: 46096.435 | F64: 46096.978 | G64: 46097.075 | H64: =IF(OR(B64="",C64=""),"",(C64-B64)*24) -> 4.3833333 | I64: =IF(OR(C64="",D64=""),"",(D64-C64)*24) -> 17.583333 | J64: =IF(OR(D64="",E64=""),"",(E64-D64)*24) -> -2 | K64: =IF(OR(E64="",F64=""),"",(F64-E64)*24) -> 13.016667 | L64: =IF(OR(F64="",G64=""),"",(G64-F64)*24) -> 2.3333333 | M64: =IF(COUNT(B64:G64)<6,"Missing timestamp",IF(MIN(H64:L64)<0,"Negative duration","OK")) -> Negative duration | N64: =IF($M64="OK",H64,"") | O64: =IF($M64="OK",I64,"") | P64: =IF($M64="OK",J64,"") | Q64: =IF($M64="OK",K64,"") | R64: =IF($M64="OK",L64,"") | S64: =IF(M64="OK",SUM(N64:R64),"")
A65: ORD-0166 | B65: 46095.974 | C65: 46096.185 | D65: 46096.631 | F65: 46097.012 | G65: 46097.12 | H65: =IF(OR(B65="",C65=""),"",(C65-B65)*24) -> 5.05 | I65: =IF(OR(C65="",D65=""),"",(D65-C65)*24) -> 10.7 | J65: =IF(OR(D65="",E65=""),"",(E65-D65)*24) | K65: =IF(OR(E65="",F65=""),"",(F65-E65)*24) | L65: =IF(OR(F65="",G65=""),"",(G65-F65)*24) -> 2.6 | M65: =IF(COUNT(B65:G65)<6,"Missing timestamp",IF(MIN(H65:L65)<0,"Negative duration","OK")) -> Missing timestamp | N65: =IF($M65="OK",H65,"") | O65: =IF($M65="OK",I65,"") | P65: =IF($M65="OK",J65,"") | Q65: =IF($M65="OK",K65,"") | R65: =IF($M65="OK",L65,"") | S65: =IF(M65="OK",SUM(N65:R65),"")
A66: ORD-0130 | B66: 46096.009 | C66: 46096.189 | D66: 46096.863 | E66: 46097.461 | F66: 46097.647 | G66: 46097.774 | H66: =IF(OR(B66="",C66=""),"",(C66-B66)*24) -> 4.3166667 | I66: =IF(OR(C66="",D66=""),"",(D66-C66)*24) -> 16.166667 | J66: =IF(OR(D66="",E66=""),"",(E66-D66)*24) -> 14.366667 | K66: =IF(OR(E66="",F66=""),"",(F66-E66)*24) -> 4.45 | L66: =IF(OR(F66="",G66=""),"",(G66-F66)*24) -> 3.05 | M66: =IF(COUNT(B66:G66)<6,"Missing timestamp",IF(MIN(H66:L66)<0,"Negative duration","OK")) -> OK | N66: =IF($M66="OK",H66,"") -> 4.3166667 | O66: =IF($M66="OK",I66,"") -> 16.166667 | P66: =IF($M66="OK",J66,"") -> 14.366667 | Q66: =IF($M66="OK",K66,"") -> 4.45 | R66: =IF($M66="OK",L66,"") -> 3.05 | S66: =IF(M66="OK",SUM(N66:R66),"") -> 42.35
A67: ORD-0052 | B67: 46096.037 | C67: 46096.242 | D67: 46097.048 | E67: 46097.544 | F67: 46098.07 | G67: 46098.163 | H67: =IF(OR(B67="",C67=""),"",(C67-B67)*24) -> 4.9 | I67: =IF(OR(C67="",D67=""),"",(D67-C67)*24) -> 19.35 | J67: =IF(OR(D67="",E67=""),"",(E67-D67)*24) -> 11.9 | K67: =IF(OR(E67="",F67=""),"",(F67-E67)*24) -> 12.633333 | L67: =IF(OR(F67="",G67=""),"",(G67-F67)*24) -> 2.2333333 | M67: =IF(COUNT(B67:G67)<6,"Missing timestamp",IF(MIN(H67:L67)<0,"Negative duration","OK")) -> OK | N67: =IF($M67="OK",H67,"") -> 4.9 | O67: =IF($M67="OK",I67,"") -> 19.35 | P67: =IF($M67="OK",J67,"") -> 11.9 | Q67: =IF($M67="OK",K67,"") -> 12.633333 | R67: =IF($M67="OK",L67,"") -> 2.2333333 | S67: =IF(M67="OK",SUM(N67:R67),"") -> 51.016667
A68: ORD-0119 | B68: 46096.088 | C68: 46096.422 | D68: 46097.242 | E68: 46098.26 | F68: 46098.55 | G68: 46098.665 | H68: =IF(OR(B68="",C68=""),"",(C68-B68)*24) -> 8 | I68: =IF(OR(C68="",D68=""),"",(D68-C68)*24) -> 19.683333 | J68: =IF(OR(D68="",E68=""),"",(E68-D68)*24) -> 24.45 | K68: =IF(OR(E68="",F68=""),"",(F68-E68)*24) -> 6.95 | L68: =IF(OR(F68="",G68=""),"",(G68-F68)*24) -> 2.7666667 | M68: =IF(COUNT(B68:G68)<6,"Missing timestamp",IF(MIN(H68:L68)<0,"Negative duration","OK")) -> OK | N68: =IF($M68="OK",H68,"") -> 8 | O68: =IF($M68="OK",I68,"") -> 19.683333 | P68: =IF($M68="OK",J68,"") -> 24.45 | Q68: =IF($M68="OK",K68,"") -> 6.95 | R68: =IF($M68="OK",L68,"") -> 2.7666667 | S68: =IF(M68="OK",SUM(N68:R68),"") -> 61.85
A69: ORD-0011 | B69: 46096.102 | C69: 46096.198 | D69: 46097.206 | E69: 46097.931 | F69: 46098.192 | G69: 46098.266 | H69: =IF(OR(B69="",C69=""),"",(C69-B69)*24) -> 2.3 | I69: =IF(OR(C69="",D69=""),"",(D69-C69)*24) -> 24.2 | J69: =IF(OR(D69="",E69=""),"",(E69-D69)*24) -> 17.4 | K69: =IF(OR(E69="",F69=""),"",(F69-E69)*24) -> 6.25 | L69: =IF(OR(F69="",G69=""),"",(G69-F69)*24) -> 1.7833333 | M69: =IF(COUNT(B69:G69)<6,"Missing timestamp",IF(MIN(H69:L69)<0,"Negative duration","OK")) -> OK | N69: =IF($M69="OK",H69,"") -> 2.3 | O69: =IF($M69="OK",I69,"") -> 24.2 | P69: =IF($M69="OK",J69,"") -> 17.4 | Q69: =IF($M69="OK",K69,"") -> 6.25 | R69: =IF($M69="OK",L69,"") -> 1.7833333 | S69: =IF(M69="OK",SUM(N69:R69),"") -> 51.933333
...

Sheet Recommendation
A1: Recommendation (what a manager would do)
A2: SYNTHETIC DATA - personal learning project. Not company data. No real savings or impact.
A4: Findings (formula-driven, update with inputs)
